Workbook
Name Architecture_Practice_USA: #REF!
Name Architecture_Practice_USA: #REF!
Name Architecture_Practice_USA: #REF!
Name Architecture_Practice_USA: Picklist!#REF!
Name Cloud_Practice_India: #REF!
Name Cloud_Practice_India: #REF!
Name Cloud_Practice_India: #REF!
Name Cloud_Practice_India: Picklist!#REF!
Name Cloud_Practice_USA: #REF!
Name Cloud_Practice_USA: #REF!
Name Cloud_Practice_USA: #REF!
Name Cloud_Practice_USA: Picklist!#REF!
Name CPM_Practice_India: #REF!
Name CPM_Practice_India: #REF!
Name CPM_Practice_India: #REF!
Name CPM_Practice_India: Picklist!#REF!
Name CPM_Practice_USA: #REF!
Name CPM_Practice_USA: #REF!
Name CPM_Practice_USA: #REF!
Name CPM_Practice_USA: Picklist!#REF!
Name EPM_Practice_India: #REF!
Name EPM_Practice_India: #REF!
Name EPM_Practice_India: #REF!
Name EPM_Practice_India: Picklist!#REF!
Name EPM_Practice_USA: #REF!
Name EPM_Practice_USA: #REF!
Name EPM_Practice_USA: #REF!
Name EPM_Practice_USA: Picklist!#REF!
Name ERP_Practice_India: #REF!
Name ERP_Practice_India: #REF!
Name ERP_Practice_India: #REF!
Name ERP_Practice_India: Picklist!#REF!
Name ERP_Practice_USA: #REF!
Name ERP_Practice_USA: #REF!
Name ERP_Practice_USA: #REF!
Name ERP_Practice_USA: Picklist!#REF!
Name Functional_Practice_USA: #REF!
Name Functional_Practice_USA: #REF!
Name Functional_Practice_USA: #REF!
Name Functional_Practice_USA: Picklist!#REF!
Name PS_Practice_USA: #REF!
Name PS_Practice_USA: #REF!
Name PS_Practice_USA: #REF!
Name PS_Practice_USA: Picklist!#REF!
Name TS_Practice_India: #REF!
Name TS_Practice_India: #REF!
Name TS_Practice_India: #REF!
Name TS_Practice_India: Picklist!#REF!
Name TS_Practice_USA: #REF!
Name TS_Practice_USA: #REF!
Name TS_Practice_USA: #REF!
Name TS_Practice_USA: Picklist!#REF!

Sheet Summary
A1: General Information | F1: Blended Rate (w/Discount) | G1: Net Margin $ (w/Discount) | H1: Net Margin % (w/Discount)
A3: Client Name (Partner Name): | B3: ='Pricing Details'!B1 -> IEEE | E3: US (Goal $195) | F3: ='Pricing Details'!AT51 -> 230 | G3: ='Pricing Details'!AU51 -> 20150 | H3: ='Pricing Details'!AV51 -> 0.2826087
A4: Capability: | B4: =IF('Pricing Details'!B2=0," ",'Pricing Details'!B2) -> IT
A5: Service: | B5: =IF('Pricing Details'!B3=0," ",'Pricing Details'!B3) -> Change Management | E5: India (Goal $50) | F5: ='Pricing Details'!AT52 -> 0 | G5: ='Pricing Details'!AU52 -> 0 | H5: ='Pricing Details'!AV52 -> 0
A6: Type: | B6: ='Pricing Details'!F2 -> Expansion
A7: Pricing Date: | B7: ='Pricing Details'!D1 -> 46013 | E7: Total | F7: ='Pricing Details'!AT53 -> 230 | G7: ='Pricing Details'!AU53 -> 20150 | H7: ='Pricing Details'!AV53 -> 0.2826087
A8: Sales Rep: | B8: =IF('Pricing Details'!D2=0," ",'Pricing Details'!D2) -> Camryn Barry
A9: Presales / Delivery: | B9: =IF('Pricing Details'!D3=0," ",'Pricing Details'!D3) -> Jai Jain
A10: Engagement Lead: | B10: =IF('Pricing Details'!D4=0," ",'Pricing Details'!D4) -> Melissa O'Blenis
A12: Fees
A14: Contract Type: | B14: ='Pricing Details'!B4 -> T&M
A15: Discount Type: | B15: ='Pricing Details'!AR4 -> Hourly Rate
A16: Total Fees: | B16: ='Pricing Details'!AS44 -> 85250
A17: Total Discount: | B17: =IF('Pricing Details'!AR4="Bottom Line",'Pricing Details'!$AS$45,'Pricing Details'!$AS$44-'Pricing Details'!$AU$44) -> 13950
A18: Total Discounted Fee: | B18: =IF('Pricing Details'!$AR$4="Bottom Line",'Pricing Details'!AU45,'Pricing Details'!AU44) -> 71300

Sheet Pricing Details
A1: Client Name (Partner Name): | B1: IEEE | C1: Pricing Date: | D1: 46013 | F1: v1.7.6 | H1: Cells with purple headers can be edited
A2: Capability/Practice Area: | B2: IT | C2: Sales Rep: | D2: Camryn Barry | E2: Type: | F2: Expansion
A3: Service /Project Type: | B3: Change Management | C3: Presales/Delivery: | D3: Jai Jain | E3: Risk Profile: | F3: Low
A4: Contract Type: | B4: T&M | C4: Engagement Lead: | D4: Melissa O'Blenis | E4: Project Start Date: | F4: 46055 | G4: *If you need more than 4 months, unhide the columns between J & AP | AQ4: Discount Type | AR4: Hourly Rate | AS4: NOTE: Hourly Rate and Bottom Line discounts cannot be combined.
A5: Practice | B5: Certinia Resource Role (role required for the project if TBD; resource's actual role if staffed at the time of pricing) | C5: Project Role (description of skill/area needed, name of resource) If Subcontractor include Resource Name and Company and Certinia Resource Role. | D5: Potential Resource | E5: Resource Location | F5: Standard Hourly Rate | G5: =EOMONTH(F4,0) -> 46081 | H5: =EOMONTH(G5,1) -> 46112 | I5: =EOMONTH(H5,1) -> 46142 | J5: =EOMONTH(I5,1) -> 46173 | K5: =EOMONTH(J5,1) -> 46203 | L5: =EOMONTH(K5,1) -> 46234 | M5: =EOMONTH(L5,1) -> 46265 | N5: =EOMONTH(M5,1) -> 46295 | O5: =EOMONTH(N5,1) -> 46326 | ... AP5: =EOMONTH(AO5,1) -> 47149 | AQ5: Discount % Applied by Sales Team | AR5: Total Hours (by Role) | AS5: Total Fee (by Role) | AT5: Sales Discount Applied (by Role) | AU5: Total Fee (w/Rate Discount) | AV5: Hourly Rate after Discount (Hourly) | AW5: Hourly Rate after Discount (Bottom Line) | AX5: Net Margin % by Role | BI5: Average Cost by Role | BJ5: Total Net Cost by Role | BK5: Total Net Margin by Role | BL5: Net Margin % by Role
G6: Month 1 | H6: Month 2 | I6: Month 3 | J6: Month 4 | K6: Month 5 | L6: Month 6 | M6: Month 7 | N6: Month 8 | O6: Month 9 | P6: Month 10 | Q6: Month 11 | R6: Month 12 | S6: Month 13 | T6: Month 14 | U6: Month 15 | V6: Month 16 | W6: Month 17 | X6: Month 18 | Y6: Month 19 | Z6: Month 20 | AA6: Month 21 | AB6: Month 22 | AC6: Month 23 | AD6: Month 24 | AE6: Month 25 | AF6: Month 26 | AG6: Month 27 | AH6: Month 28 | AI6: Month 29 | AJ6: Month 30 | AK6: Month 31 | AL6: Month 32 | AM6: Month 33 | AN6: Month 34 | AO6: Month 35 | AP6: Month 36
G7: =_xlfn.XLOOKUP(G$5,Picklist!$T$2:$T$61,Picklist!$U$2:$U$61) -> 152 | H7: =_xlfn.XLOOKUP(H$5,Picklist!$T$2:$T$61,Picklist!$U$2:$U$61) -> 176 | I7: =_xlfn.XLOOKUP(I$5,Picklist!$T$2:$T$61,Picklist!$U$2:$U$61) -> 176 | J7: =_xlfn.XLOOKUP(J$5,Picklist!$T$2:$T$61,Picklist!$U$2:$U$61) -> 160 | K7: =_xlfn.XLOOKUP(K$5,Picklist!$T$2:$T$61,Picklist!$U$2:$U$61) -> 176 | L7: =_xlfn.XLOOKUP(L$5,Picklist!$T$2:$T$61,Picklist!$U$2:$U$61) -> 176 | M7: =_xlfn.XLOOKUP(M$5,Picklist!$T$2:$T$61,Picklist!$U$2:$U$61) -> 168 | N7: =_xlfn.XLOOKUP(N$5,Picklist!$T$2:$T$61,Picklist!$U$2:$U$61) -> 168 | ... AP7: =_xlfn.XLOOKUP(AP$5,Picklist!$T$2:$T$61,Picklist!$U$2:$U$61) -> 176
G8: Phase | H8: Phase | I8: Phase | J8: Phase | K8: Phase | L8: Phase | M8: Phase | N8: Phase | O8: Phase | P8: Phase | Q8: Phase | R8: Phase | S8: Phase | T8: Phase | U8: Phase | V8: Phase | W8: Phase | X8: Phase | Y8: Phase | Z8: Phase | AA8: Phase | AB8: Phase | AC8: Phase | AD8: Phase | AE8: Phase | AF8: Phase | AG8: Phase | AH8: Phase | AI8: Phase | AJ8: Phase | AK8: Phase | AL8: Phase | AM8: Phase | AN8: Phase | AO8: Phase | AP8: Phase
A9: EPM_Practice_USA | B9: Sr. Change Manager | C9: Sr. Change Manager | D9: Melissa O'Blenis | E9: {=IFERROR(INDEX(_xlfn.TEXTSPLIT(A9,"_"),3),"")} -> USA | F9: =_xlfn.XLOOKUP(_xlfn.CONCAT(A9,B9),Picklist!$O$3:$O$332,Picklist!$P$3:$P$332,"Choose Existing Role",0) -> 275 | G9: 50 | H9: 80 | I9: 90 | J9: 90 | AQ9: 0.16363 | AR9: =SUM(G9:AP9) -> 310 | AS9: =IFERROR((F9*AR9),0) -> 85250 | AT9: =ROUND((-AS9*AQ9),2) -> -13949.46 | AU9: =AR9*AV9 -> 71300 | AV9: =IFERROR(ROUND((F9*(1-AQ9)),2),0) -> 230 | AW9: =IFERROR(IF($AR$4="Hourly Rate",0,ROUND((F9*(1-$AQ$45)),2)),0) -> 0 | AX9: =BL9 -> 0.2826087 | BI9: =_xlfn.XLOOKUP((_xlfn.CONCAT(A9,B9)),Picklist!$O$3:$O$292,Picklist!$Q$3:$Q$292,"",0) -> 165 | BJ9: =IFERROR(AR9*BI9,0) -> 51150 | BK9: =(AU9*(1-$AQ$45))-BJ9 -> 20150 | BL9: =IFERROR(((AU9*(1-$AQ$45))-BJ9)/(AU9*(1-$AQ$45)),0) -> 0.2826087
E10: {=IFERROR(INDEX(_xlfn.TEXTSPLIT(A10,"_"),3),"")} | F10: =_xlfn.XLOOKUP(_xlfn.CONCAT(A10,B10),Picklist!$O$3:$O$332,Picklist!$P$3:$P$332,"Choose Existing Role",0) -> 0 | AQ10: 0 | AR10: =SUM(G10:AP10) -> 0 | AS10: =IFERROR((F10*AR10),0) -> 0 | AT10: =ROUND((-AS10*AQ10),2) -> 0 | AU10: =AR10*AV10 -> 0 | AV10: =IFERROR(ROUND((F10*(1-AQ10)),2),0) -> 0 | AW10: =IFERROR(IF($AR$4="Hourly Rate",0,ROUND((F10*(1-$AQ$45)),2)),0) -> 0 | AX10: =BL10 -> 0 | BI10: =_xlfn.XLOOKUP((_xlfn.CONCAT(A10,B10)),Picklist!$O$3:$O$292,Picklist!$Q$3:$Q$292,"",0) -> 0 | BJ10: =IFERROR(AR10*BI10,0) -> 0 | BK10: =(AU10*(1-$AQ$45))-BJ10 -> 0 | BL10: =IFERROR(((AU10*(1-$AQ$45))-BJ10)/(AU10*(1-$AQ$45)),0) -> 0
E11: {=IFERROR(INDEX(_xlfn.TEXTSPLIT(A11,"_"),3),"")} | F11: =_xlfn.XLOOKUP(_xlfn.CONCAT(A11,B11),Picklist!$O$3:$O$332,Picklist!$P$3:$P$332,"Choose Existing Role",0) -> 0 | AQ11: 0 | AR11: =SUM(G11:AP11) -> 0 | AS11: =IFERROR((F11*AR11),0) -> 0 | AT11: =ROUND((-AS11*AQ11),2) -> 0 | AU11: =AR11*AV11 -> 0 | AV11: =IFERROR(ROUND((F11*(1-AQ11)),2),0) -> 0 | AW11: =IFERROR(IF($AR$4="Hourly Rate",0,ROUND((F11*(1-$AQ$45)),2)),0) -> 0 | AX11: =BL11 -> 0 | BI11: =_xlfn.XLOOKUP((_xlfn.CONCAT(A11,B11)),Picklist!$O$3:$O$292,Picklist!$Q$3:$Q$292,"",0) -> 0 | BJ11: =IFERROR(AR11*BI11,0) -> 0 | BK11: =(AU11*(1-$AQ$45))-BJ11 -> 0 | BL11: =IFERROR(((AU11*(1-$AQ$45))-BJ11)/(AU11*(1-$AQ$45)),0) -> 0
E12: {=IFERROR(INDEX(_xlfn.TEXTSPLIT(A12,"_"),3),"")} | F12: =_xlfn.XLOOKUP(_xlfn.CONCAT(A12,B12),Picklist!$O$3:$O$332,Picklist!$P$3:$P$332,"Choose Existing Role",0) -> 0 | AQ12: 0 | AR12: =SUM(G12:AP12) -> 0 | AS12: =IFERROR((F12*AR12),0) -> 0 | AT12: =ROUND((-AS12*AQ12),2) -> 0 | AU12: =AR12*AV12 -> 0 | AV12: =IFERROR(ROUND((F12*(1-AQ12)),2),0) -> 0 | AW12: =IFERROR(IF($AR$4="Hourly Rate",0,ROUND((F12*(1-$AQ$45)),2)),0) -> 0 | AX12: =BL12 -> 0 | BI12: =_xlfn.XLOOKUP((_xlfn.CONCAT(A12,B12)),Picklist!$O$3:$O$292,Picklist!$Q$3:$Q$292,"",0) -> 0 | BJ12: =IFERROR(AR12*BI12,0) -> 0 | BK12: =(AU12*(1-$AQ$45))-BJ12 -> 0 | BL12: =IFERROR(((AU12*(1-$AQ$45))-BJ12)/(AU12*(1-$AQ$45)),0) -> 0
E13: {=IFERROR(INDEX(_xlfn.TEXTSPLIT(A13,"_"),3),"")} | F13: =_xlfn.XLOOKUP(_xlfn.CONCAT(A13,B13),Picklist!$O$3:$O$332,Picklist!$P$3:$P$332,"Choose Existing Role",0) -> 0 | AQ13: 0 | AR13: =SUM(G13:AP13) -> 0 | AS13: =IFERROR((F13*AR13),0) -> 0 | AT13: =ROUND((-AS13*AQ13),2) -> 0 | AU13: =AR13*AV13 -> 0 | AV13: =IFERROR(ROUND((F13*(1-AQ13)),2),0) -> 0 | AW13: =IFERROR(IF($AR$4="Hourly Rate",0,ROUND((F13*(1-$AQ$45)),2)),0) -> 0 | AX13: =BL13 -> 0 | BI13: =_xlfn.XLOOKUP((_xlfn.CONCAT(A13,B13)),Picklist!$O$3:$O$292,Picklist!$Q$3:$Q$292,"",0) -> 0 | BJ13: =IFERROR(AR13*BI13,0) -> 0 | BK13: =(AU13*(1-$AQ$45))-BJ13 -> 0 | BL13: =IFERROR(((AU13*(1-$AQ$45))-BJ13)/(AU13*(1-$AQ$45)),0) -> 0
E14: {=IFERROR(INDEX(_xlfn.TEXTSPLIT(A14,"_"),3),"")} | F14: =_xlfn.XLOOKUP(_xlfn.CONCAT(A14,B14),Picklist!$O$3:$O$332,Picklist!$P$3:$P$332,"Choose Existing Role",0) -> 0 | AQ14: 0 | AR14: =SUM(G14:AP14) -> 0 | AS14: =IFERROR((F14*AR14),0) -> 0 | AT14: =ROUND((-AS14*AQ14),2) -> 0 | AU14: =AR14*AV14 -> 0 | AV14: =IFERROR(ROUND((F14*(1-AQ14)),2),0) -> 0 | AW14: =IFERROR(IF($AR$4="Hourly Rate",0,ROUND((F14*(1-$AQ$45)),2)),0) -> 0 | AX14: =BL14 -> 0 | BI14: =_xlfn.XLOOKUP((_xlfn.CONCAT(A14,B14)),Picklist!$O$3:$O$292,Picklist!$Q$3:$Q$292,"",0) -> 0 | BJ14: =IFERROR(AR14*BI14,0) -> 0 | BK14: =(AU14*(1-$AQ$45))-BJ14 -> 0 | BL14: =IFERROR(((AU14*(1-$AQ$45))-BJ14)/(AU14*(1-$AQ$45)),0) -> 0
E15: {=IFERROR(INDEX(_xlfn.TEXTSPLIT(A15,"_"),3),"")} | F15: =_xlfn.XLOOKUP(_xlfn.CONCAT(A15,B15),Picklist!$O$3:$O$332,Picklist!$P$3:$P$332,"Choose Existing Role",0) -> 0 | AQ15: 0 | AR15: =SUM(G15:AP15) -> 0 | AS15: =IFERROR((F15*AR15),0) -> 0 | AT15: =ROUND((-AS15*AQ15),2) -> 0 | AU15: =AR15*AV15 -> 0 | AV15: =IFERROR(ROUND((F15*(1-AQ15)),2),0) -> 0 | AW15: =IFERROR(IF($AR$4="Hourly Rate",0,ROUND((F15*(1-$AQ$45)),2)),0) -> 0 | AX15: =BL15 -> 0 | BI15: =_xlfn.XLOOKUP((_xlfn.CONCAT(A15,B15)),Picklist!$O$3:$O$292,Picklist!$Q$3:$Q$292,"",0) -> 0 | BJ15: =IFERROR(AR15*BI15,0) -> 0 | BK15: =(AU15*(1-$AQ$45))-BJ15 -> 0 | BL15: =IFERROR(((AU15*(1-$AQ$45))-BJ15)/(AU15*(1-$AQ$45)),0) -> 0
E16: {=IFERROR(INDEX(_xlfn.TEXTSPLIT(A16,"_"),3),"")} | F16: =_xlfn.XLOOKUP(_xlfn.CONCAT(A16,B16),Picklist!$O$3:$O$332,Picklist!$P$3:$P$332,"Choose Existing Role",0) -> 0 | AQ16: 0 | AR16: =SUM(G16:AP16) -> 0 | AS16: =IFERROR((F16*AR16),0) -> 0 | AT16: =ROUND((-AS16*AQ16),2) -> 0 | AU16: =AR16*AV16 -> 0 | AV16: =IFERROR(ROUND((F16*(1-AQ16)),2),0) -> 0 | AW16: =IFERROR(IF($AR$4="Hourly Rate",0,ROUND((F16*(1-$AQ$45)),2)),0) -> 0 | AX16: =BL16 -> 0 | BI16: =_xlfn.XLOOKUP((_xlfn.CONCAT(A16,B16)),Picklist!$O$3:$O$292,Picklist!$Q$3:$Q$292,"",0) -> 0 | BJ16: =IFERROR(AR16*BI16,0) -> 0 | BK16: =(AU16*(1-$AQ$45))-BJ16 -> 0 | BL16: =IFERROR(((AU16*(1-$AQ$45))-BJ16)/(AU16*(1-$AQ$45)),0) -> 0
E17: {=IFERROR(INDEX(_xlfn.TEXTSPLIT(A17,"_"),3),"")} | F17: =_xlfn.XLOOKUP(_xlfn.CONCAT(A17,B17),Picklist!$O$3:$O$332,Picklist!$P$3:$P$332,"Choose Existing Role",0) -> 0 | AQ17: 0 | AR17: =SUM(G17:AP17) -> 0 | AS17: =IFERROR((F17*AR17),0) -> 0 | AT17: =ROUND((-AS17*AQ17),2) -> 0 | AU17: =AR17*AV17 -> 0 | AV17: =IFERROR(ROUND((F17*(1-AQ17)),2),0) -> 0 | AW17: =IFERROR(IF($AR$4="Hourly Rate",0,ROUND((F17*(1-$AQ$45)),2)),0) -> 0 | AX17: =BL17 -> 0 | BI17: =_xlfn.XLOOKUP((_xlfn.CONCAT(A17,B17)),Picklist!$O$3:$O$292,Picklist!$Q$3:$Q$292,"",0) -> 0 | BJ17: =IFERROR(AR17*BI17,0) -> 0 | BK17: =(AU17*(1-$AQ$45))-BJ17 -> 0 | BL17: =IFERROR(((AU17*(1-$AQ$45))-BJ17)/(AU17*(1-$AQ$45)),0) -> 0
E18: {=IFERROR(INDEX(_xlfn.TEXTSPLIT(A18,"_"),3),"")} | F18: =_xlfn.XLOOKUP(_xlfn.CONCAT(A18,B18),Picklist!$O$3:$O$332,Picklist!$P$3:$P$332,"Choose Existing Role",0) -> 0 | AQ18: 0 | AR18: =SUM(G18:AP18) -> 0 | AS18: =IFERROR((F18*AR18),0) -> 0 | AT18: =ROUND((-AS18*AQ18),2) -> 0 | AU18: =AR18*AV18 -> 0 | AV18: =IFERROR(ROUND((F18*(1-AQ18)),2),0) -> 0 | AW18: =IFERROR(IF($AR$4="Hourly Rate",0,ROUND((F18*(1-$AQ$45)),2)),0) -> 0 | AX18: =BL18 -> 0 | BI18: =_xlfn.XLOOKUP((_xlfn.CONCAT(A18,B18)),Picklist!$O$3:$O$292,Picklist!$Q$3:$Q$292,"",0) -> 0 | BJ18: =IFERROR(AR18*BI18,0) -> 0 | BK18: =(AU18*(1-$AQ$45))-BJ18 -> 0 | BL18: =IFERROR(((AU18*(1-$AQ$45))-BJ18)/(AU18*(1-$AQ$45)),0) -> 0
E19: {=IFERROR(INDEX(_xlfn.TEXTSPLIT(A19,"_"),3),"")} | F19: =_xlfn.XLOOKUP(_xlfn.CONCAT(A19,B19),Picklist!$O$3:$O$332,Picklist!$P$3:$P$332,"Choose Existing Role",0) -> 0 | AQ19: 0 | AR19: =SUM(G19:AP19) -> 0 | AS19: =IFERROR((F19*AR19),0) -> 0 | AT19: =ROUND((-AS19*AQ19),2) -> 0 | AU19: =AR19*AV19 -> 0 | AV19: =IFERROR(ROUND((F19*(1-AQ19)),2),0) -> 0 | AW19: =IFERROR(IF($AR$4="Hourly Rate",0,ROUND((F19*(1-$AQ$45)),2)),0) -> 0 | AX19: =BL19 -> 0 | BI19: =_xlfn.XLOOKUP((_xlfn.CONCAT(A19,B19)),Picklist!$O$3:$O$292,Picklist!$Q$3:$Q$292,"",0) -> 0 | BJ19: =IFERROR(AR19*BI19,0) -> 0 | BK19: =(AU19*(1-$AQ$45))-BJ19 -> 0 | BL19: =IFERROR(((AU19*(1-$AQ$45))-BJ19)/(AU19*(1-$AQ$45)),0) -> 0
E20: {=IFERROR(INDEX(_xlfn.TEXTSPLIT(A20,"_"),3),"")} | F20: =_xlfn.XLOOKUP(_xlfn.CONCAT(A20,B20),Picklist!$O$3:$O$332,Picklist!$P$3:$P$332,"Choose Existing Role",0) -> 0 | AQ20: 0 | AR20: =SUM(G20:AP20) -> 0 | AS20: =IFERROR((F20*AR20),0) -> 0 | AT20: =ROUND((-AS20*AQ20),2) -> 0 | AU20: =AR20*AV20 -> 0 | AV20: =IFERROR(ROUND((F20*(1-AQ20)),2),0) -> 0 | AW20: =IFERROR(IF($AR$4="Hourly Rate",0,ROUND((F20*(1-$AQ$45)),2)),0) -> 0 | AX20: =BL20 -> 0 | BI20: =_xlfn.XLOOKUP((_xlfn.CONCAT(A20,B20)),Picklist!$O$3:$O$292,Picklist!$Q$3:$Q$292,"",0) -> 0 | BJ20: =IFERROR(AR20*BI20,0) -> 0 | BK20: =(AU20*(1-$AQ$45))-BJ20 -> 0 | BL20: =IFERROR(((AU20*(1-$AQ$45))-BJ20)/(AU20*(1-$AQ$45)),0) -> 0
E21: {=IFERROR(INDEX(_xlfn.TEXTSPLIT(A21,"_"),3),"")} | F21: =_xlfn.XLOOKUP(_xlfn.CONCAT(A21,B21),Picklist!$O$3:$O$332,Picklist!$P$3:$P$332,"Choose Existing Role",0) -> 0 | AQ21: 0 | AR21: =SUM(G21:AP21) -> 0 | AS21: =IFERROR((F21*AR21),0) -> 0 | AT21: =ROUND((-AS21*AQ21),2) -> 0 | AU21: =AR21*AV21 -> 0 | AV21: =IFERROR(ROUND((F21*(1-AQ21)),2),0) -> 0 | AW21: =IFERROR(IF($AR$4="Hourly Rate",0,ROUND((F21*(1-$AQ$45)),2)),0) -> 0 | AX21: =BL21 -> 0 | BI21: =_xlfn.XLOOKUP((_xlfn.CONCAT(A21,B21)),Picklist!$O$3:$O$292,Picklist!$Q$3:$Q$292,"",0) -> 0 | BJ21: =IFERROR(AR21*BI21,0) -> 0 | BK21: =(AU21*(1-$AQ$45))-BJ21 -> 0 | BL21: =IFERROR(((AU21*(1-$AQ$45))-BJ21)/(AU21*(1-$AQ$45)),0) -> 0
... E43: {=IFERROR(INDEX(_xlfn.TEXTSPLIT(A43,"_"),3),"")} | F43: =_xlfn.XLOOKUP(_xlfn.CONCAT(A43,B43),Picklist!$O$3:$O$332,Picklist!$P$3:$P$332,"Choose Existing Role",0) -> 0 | AQ43: 0 | AR43: =SUM(G43:AP43) -> 0 | AS43: =IFERROR((F43*AR43),0) -> 0 | AT43: =ROUND((-AS43*AQ43),2) -> 0 | AU43: =AR43*AV43 -> 0 | AV43: =IFERROR(ROUND((F43*(1-AQ43)),2),0) -> 0 | AW43: =IFERROR(IF($AR$4="Hourly Rate",0,ROUND((F43*(1-$AQ$45)),2)),0) -> 0 | AX43: =BL43 -> 0 | BI43: =_xlfn.XLOOKUP((_xlfn.CONCAT(A43,B43)),Picklist!$O$3:$O$292,Picklist!$Q$3:$Q$292,"",0) -> 0 | BJ43: =IFERROR(AR43*BI43,0) -> 0 | BK43: =(AU43*(1-$AQ$45))-BJ43 -> 0 | BL43: =IFERROR(((AU43*(1-$AQ$45))-BJ43)/(AU43*(1-$AQ$45)),0) -> 0
A44: *If you need more than 10 resources, unhide the rows between 19 & 44 | F44: =IFERROR(AVERAGEIF(F9:F43,"<>0"),0) -> 275 | G44: =SUM(G9:G43) -> 50 | H44: =SUM(H9:H43) -> 80 | I44: =SUM(I9:I43) -> 90 | J44: =SUM(J9:J43) -> 90 | K44: =SUM(K9:K43) -> 0 | L44: =SUM(L9:L43) -> 0 | M44: =SUM(M9:M43) -> 0 | N44: =SUM(N9:N43) -> 0 | ... AP44: =SUM(AP9:AP43) -> 0 | AQ44: =IFERROR(AVERAGEIF(AQ9:AQ43,"<>0"),0) -> 0.16363 | AR44: =SUM(AR9:AR43) -> 310 | AS44: =SUM(AS9:AS43) -> 85250 | AT44: =SUM(AT9:AT43) -> -13949.46 | AU44: =SUM(AU9:AU43) -> 71300 | BI44: =AVERAGEIF(BI9:BI43,"<>0") -> 165 | BJ44: =SUM(BJ9:BJ43) -> 51150 | BK44: =SUM(BK9:BK43) -> 20150 | BL44: =IFERROR((AU44-BJ44)/AU44,0) -> 0.2826087
AR45: Bottom Line Disc % | AS45: =ROUND((-AS44*AQ45),2) -> 0 | AT45: Bottom Line Discount Amount | AU45: =IFERROR(IF($AR$4="Hourly Rate",0,AS44+AS45),0) -> 0 | AV45: Total Fee w/Bottom Line Discount
F46: Average Rate | G46: Monthly Total Hours | H46: Monthly Total Hours | I46: Monthly Total Hours | J46: Monthly Total Hours | K46: Monthly Total Hours | L46: Monthly Total Hours | M46: Monthly Total Hours | N46: Monthly Total Hours | O46: Monthly Total Hours | P46: Monthly Total Hours | Q46: Monthly Total Hours | R46: Monthly Total Hours | S46: Monthly Total Hours | T46: Monthly Total Hours | U46: Monthly Total Hours | V46: Monthly Total Hours | W46: Monthly Total Hours | X46: Monthly Total Hours | Y46: Monthly Total Hours | Z46: Monthly Total Hours | AA46: Monthly Total Hours | AB46: Monthly Total Hours | AC46: Monthly Total Hours | AD46: Monthly Total Hours | AE46: Monthly Total Hours | AF46: Monthly Total Hours | AG46: Monthly Total Hours | AH46: Monthly Total Hours | AI46: Monthly Total Hours | AJ46: Monthly Total Hours | AK46: Monthly Total Hours | AL46: Monthly Total Hours | AM46: Monthly Total Hours | AN46: Monthly Total Hours | AO46: Monthly Total Hours | AP46: Monthly Total Hours | AQ46: Average Discount Applied | AR46: Total Hours | AS46: TCV | AT46: Total Discount | AU46: TCV (w/Discount) | BI46: Average Cost | BJ46: Total Cost | BK46: Total Margin | BL46: Margin %
F47: TCV By Month | G47: =(SUMPRODUCT(G9:G43,$AV$9:$AV$43))-(ROUND(((SUMPRODUCT(G9:G43,$AV9:$AV43))*$AQ$45),2)) -> 11500 | H47: =(SUMPRODUCT(H9:H43,$AV$9:$AV$43))-(ROUND(((SUMPRODUCT(H9:H43,$AV9:$AV43))*$AQ$45),2)) -> 18400 | I47: =(SUMPRODUCT(I9:I43,$AV$9:$AV$43))-(ROUND(((SUMPRODUCT(I9:I43,$AV9:$AV43))*$AQ$45),2)) -> 20700 | J47: =(SUMPRODUCT(J9:J43,$AV$9:$AV$43))-(ROUND(((SUMPRODUCT(J9:J43,$AV9:$AV43))*$AQ$45),2)) -> 20700 | K47: =(SUMPRODUCT(K9:K43,$AV$9:$AV$43))-(ROUND(((SUMPRODUCT(K9:K43,$AV9:$AV43))*$AQ$45),2)) -> 0 | L47: =(SUMPRODUCT(L9:L43,$AV$9:$AV$43))-(ROUND(((SUMPRODUCT(L9:L43,$AV9:$AV43))*$AQ$45),2)) -> 0 | M47: =(SUMPRODUCT(M9:M43,$AV$9:$AV$43))-(ROUND(((SUMPRODUCT(M9:M43,$AV9:$AV43))*$AQ$45),2)) -> 0 | N47: =(SUMPRODUCT(N9:N43,$AV$9:$AV$43))-(ROUND(((SUMPRODUCT(N9:N43,$AV9:$AV43))*$AQ$45),2)) -> 0 | ... AP47: =(SUMPRODUCT(AP9:AP43,$AV$9:$AV$43))-(ROUND(((SUMPRODUCT(AP9:AP43,$AV9:$AV43))*$AQ$45),2)) -> 0
A50: Guiding Principles | D50: Target Net Margin | F50: Risk Profile | G50: Low | H50: Medium | I50: High | AQ50: Risk Profile | AT50: Blended Rate (w/Discount) | AU50: Net Margin $ (w/Discount) | AV50: Net Margin % (w/Discount) | AW50: Target Net Margin
A51: Avoid Milestone based or Fixed Fee Implementation projects - 20% contingency must be added for these projects | C51: T&M | D51: 0.35 | F51: Project Type | G51: Staff Aug / Support | H51: Implementation Managed Services | I51: Complex Implementation | AQ51: =F3 -> Low | AS51: US (Goal $195) | AT51: =IFERROR((SUMIFS($AU$9:$AU$43,$E$9:$E$43,"USA")*(1-AQ45))/(SUMIFS($AR$9:$AR$43,$E$9:$E$43,"USA")),0) -> 230 | AU51: =IFERROR((SUMIFS($BK$9:$BK$43,$E$9:$E$43,"USA")),0) -> 20150 | AV51: =IFERROR(IF($AQ$45=0,SUMIFS($BK$9:$BK$43,$E$9:$E$43,"USA")/SUMIFS($AU$9:$AU$43,$E$9:$E$43,"USA"),SUMIFS($BK$9:$BK$43,$E$9:$E$43,"USA")/(SUMIFS($AU$9:$AU$43,$E$9:$E$43,"USA")*(1-AQ45))),0) -> 0.2826087 | AW51: 0.35
A52: PM required for Implementation | C52: Managed Services (FF) | D52: 0.3 | F52: Team Size | G52: Small | H52: Medium | I52: Large | AS52: India (Goal $50) | AT52: =IFERROR((SUMIFS($AU$9:$AU$43,$E$9:$E$43,"India")*(1-AQ45))/(SUMIFS($AR$9:$AR$43,$E$9:$E$43,"India")),0) -> 0 | AU52: =IFERROR((SUMIFS($BK$9:$BK$43,$E$9:$E$43,"India")),0) -> 0 | AV52: =IFERROR(IF($AQ$45=0,SUMIFS($BK$9:$BK$43,$E$9:$E$43,"India")/SUMIFS($AU$9:$AU$43,$E$9:$E$43,"India"),SUMIFS($BK$9:$BK$43,$E$9:$E$43,"India")/(SUMIFS($AU$9:$AU$43,$E$9:$E$43,"India")*(1-AQ45))),0) -> 0
A53: Avoid partial utilization except Architects | F53: Scope Complexity | G53: Basic | H53: Medium | I53: Complex | AS53: Total | AT53: =IFERROR((AU44*(1-AQ45))/AR44,0) -> 230 | AU53: =BK44 -> 20150 | AV53: =IFERROR(IF($AQ$45=0,$AU$53/$AU$44,$AU$53/$AU$45),0) -> 0.2826087
A54: Bid for MS work on Implemention SOW | F54: Possible Scope Changes | G54: None | H54: Minor | I54: Major
A55: Engagement Lead role required for support projects at least at 10% utilization. All EPM/CPM Implementation projects require a Project Manager. Maritza must approve exceptions to this. | F55: Contract Value | G55: Small | H55: Medium | I55: Large
A56: Managed Services must include hours/month fixed fee, T&M can be used for overage.

Sheet Formulas
A1: Use to back into the discount when provided with hourly rates or total fee | T1: For SOW Timing Section
F2: T&M | K2: Discounted | M2: Fixed Fee | Q2: Discounted | R2: Discounted
T3: Resource Role / Hours | U3: Resource Location | V3: Months
A4: Goal Hourly Rate or Total Fee | B4: Donyati Standard Hourly Rate or Total Fee | C4: Discount % | F4: Resource Role | G4: Resource Location | H4: Total Estimated Hours | I4: Standard Hourly Rate | J4: Discounted Hourly Rate | K4: Estimated Fee | M4: Resource Role | N4: Resource Location | O4: Fixed Hours per Month | P4: Standard Hourly Rate | Q4: Hourly rate | R4: Monthly Fixed Fee | V4: 1 | W4: 2 | X4: 3 | Y4: 4 | Z4: 5 | AA4: 6 | AB4: 7 | AC4: 8 | AD4: 9 | AE4: 10 | AF4: 11 | AG4: 12 | AH4: 13 | AI4: 14 | AJ4: 15 | AK4: 16 | AL4: 17 | AM4: 18 | AN4: 19 | AO4: 20 | AP4: 21 | AQ4: 22 | AR4: 23 | AS4: 24 | AT4: 25 | AU4: 26 | AV4: 27 | AW4: 28 | AX4: 29 | AY4: 30 | AZ4: 31 | BA4: 32 | BB4: 33 | BC4: 34 | BD4: 35 | BE4: 36
A5: 230 | B5: 275 | C5: =(A5/B5)-1 -> -0.16363636 | F5: ='Pricing Details'!B9 -> Sr. Change Manager | G5: ='Pricing Details'!E9 -> USA | H5: ='Pricing Details'!AR9 -> 310 | I5: ='Pricing Details'!F9 -> 275 | J5: ='Pricing Details'!AV9 -> 230 | K5: ='Pricing Details'!AU9 -> 71300 | M5: ='Pricing Details'!B9 -> Sr. Change Manager | N5: ='Pricing Details'!E9 -> USA | O5: ='Pricing Details'!G9 -> 50 | P5: ='Pricing Details'!F9 -> 275 | Q5: ='Pricing Details'!AV9 -> 230 | R5: =O5*Q5 -> 11500 | T5: ='Pricing Details'!B9 -> Sr. Change Manager | U5: ='Pricing Details'!E9 -> USA | V5: ='Pricing Details'!G9 -> 50 | W5: ='Pricing Details'!H9 -> 80 | X5: ='Pricing Details'!I9 -> 90 | Y5: ='Pricing Details'!J9 -> 90 | Z5: ='Pricing Details'!K9 -> 0 | AA5: ='Pricing Details'!L9 -> 0 | AB5: ='Pricing Details'!M9 -> 0 | AC5: ='Pricing Details'!N9 -> 0 | ... BE5: ='Pricing Details'!AP9 -> 0
F6: ='Pricing Details'!B10 -> 0 | G6: ='Pricing Details'!E10 | H6: ='Pricing Details'!AR10 -> 0 | I6: ='Pricing Details'!F10 -> 0 | J6: ='Pricing Details'!AV10 -> 0 | K6: ='Pricing Details'!AU10 -> 0 | M6: ='Pricing Details'!B10 -> 0 | N6: ='Pricing Details'!E10 | O6: ='Pricing Details'!G10 -> 0 | P6: ='Pricing Details'!F10 -> 0 | Q6: ='Pricing Details'!AV10 -> 0 | R6: =O6*Q6 -> 0 | T6: ='Pricing Details'!B10 -> 0 | U6: ='Pricing Details'!E10 | V6: ='Pricing Details'!G10 -> 0 | W6: ='Pricing Details'!H10 -> 0 | X6: ='Pricing Details'!I10 -> 0 | Y6: ='Pricing Details'!J10 -> 0 | Z6: ='Pricing Details'!K10 -> 0 | AA6: ='Pricing Details'!L10 -> 0 | AB6: ='Pricing Details'!M10 -> 0 | AC6: ='Pricing Details'!N10 -> 0 | ... BE6: ='Pricing Details'!AP10 -> 0
A7: Use to calculate the End Date | F7: ='Pricing Details'!B11 -> 0 | G7: ='Pricing Details'!E11 | H7: ='Pricing Details'!AR11 -> 0 | I7: ='Pricing Details'!F11 -> 0 | J7: ='Pricing Details'!AV11 -> 0 | K7: ='Pricing Details'!AU11 -> 0 | M7: ='Pricing Details'!B11 -> 0 | N7: ='Pricing Details'!E11 | O7: ='Pricing Details'!G11 -> 0 | P7: ='Pricing Details'!F11 -> 0 | Q7: ='Pricing Details'!AV11 -> 0 | R7: =O7*Q7 -> 0 | T7: ='Pricing Details'!B11 -> 0 | U7: ='Pricing Details'!E11 | V7: ='Pricing Details'!G11 -> 0 | W7: ='Pricing Details'!H11 -> 0 | X7: ='Pricing Details'!I11 -> 0 | Y7: ='Pricing Details'!J11 -> 0 | Z7: ='Pricing Details'!K11 -> 0 | AA7: ='Pricing Details'!L11 -> 0 | AB7: ='Pricing Details'!M11 -> 0 | AC7: ='Pricing Details'!N11 -> 0 | ... BE7: ='Pricing Details'!AP11 -> 0
A8: Start Date | B8: # weeks | C8: End Date | F8: ='Pricing Details'!B12 -> 0 | G8: ='Pricing Details'!E12 | H8: ='Pricing Details'!AR12 -> 0 | I8: ='Pricing Details'!F12 -> 0 | J8: ='Pricing Details'!AV12 -> 0 | K8: ='Pricing Details'!AU12 -> 0 | M8: ='Pricing Details'!B12 -> 0 | N8: ='Pricing Details'!E12 | O8: ='Pricing Details'!G12 -> 0 | P8: ='Pricing Details'!F12 -> 0 | Q8: ='Pricing Details'!AV12 -> 0 | R8: =O8*Q8 -> 0 | T8: ='Pricing Details'!B12 -> 0 | U8: ='Pricing Details'!E12 | V8: ='Pricing Details'!G12 -> 0 | W8: ='Pricing Details'!H12 -> 0 | X8: ='Pricing Details'!I12 -> 0 | Y8: ='Pricing Details'!J12 -> 0 | Z8: ='Pricing Details'!K12 -> 0 | AA8: ='Pricing Details'!L12 -> 0 | AB8: ='Pricing Details'!M12 -> 0 | AC8: ='Pricing Details'!N12 -> 0 | ... BE8: ='Pricing Details'!AP12 -> 0
A9: 46023 | B9: 28 | C9: =A9+(B9*7)-3 -> 46216 | F9: ='Pricing Details'!B13 -> 0 | G9: ='Pricing Details'!E13 | H9: ='Pricing Details'!AR13 -> 0 | I9: ='Pricing Details'!F13 -> 0 | J9: ='Pricing Details'!AV13 -> 0 | K9: ='Pricing Details'!AU13 -> 0 | M9: ='Pricing Details'!B13 -> 0 | N9: ='Pricing Details'!E13 | O9: ='Pricing Details'!G13 -> 0 | P9: ='Pricing Details'!F13 -> 0 | Q9: ='Pricing Details'!AV13 -> 0 | R9: =O9*Q9 -> 0 | T9: ='Pricing Details'!B13 -> 0 | U9: ='Pricing Details'!E13 | V9: ='Pricing Details'!G13 -> 0 | W9: ='Pricing Details'!H13 -> 0 | X9: ='Pricing Details'!I13 -> 0 | Y9: ='Pricing Details'!J13 -> 0 | Z9: ='Pricing Details'!K13 -> 0 | AA9: ='Pricing Details'!L13 -> 0 | AB9: ='Pricing Details'!M13 -> 0 | AC9: ='Pricing Details'!N13 -> 0 | ... BE9: ='Pricing Details'!AP13 -> 0
F10: ='Pricing Details'!B14 -> 0 | G10: ='Pricing Details'!E14 | H10: ='Pricing Details'!AR14 -> 0 | I10: ='Pricing Details'!F14 -> 0 | J10: ='Pricing Details'!AV14 -> 0 | K10: ='Pricing Details'!AU14 -> 0 | M10: ='Pricing Details'!B14 -> 0 | N10: ='Pricing Details'!E14 | O10: ='Pricing Details'!G14 -> 0 | P10: ='Pricing Details'!F14 -> 0 | Q10: ='Pricing Details'!AV14 -> 0 | R10: =O10*Q10 -> 0 | T10: ='Pricing Details'!B14 -> 0 | U10: ='Pricing Details'!E14 | V10: ='Pricing Details'!G14 -> 0 | W10: ='Pricing Details'!H14 -> 0 | X10: ='Pricing Details'!I14 -> 0 | Y10: ='Pricing Details'!J14 -> 0 | Z10: ='Pricing Details'!K14 -> 0 | AA10: ='Pricing Details'!L14 -> 0 | AB10: ='Pricing Details'!M14 -> 0 | AC10: ='Pricing Details'!N14 -> 0 | ... BE10: ='Pricing Details'!AP14 -> 0
A11: Use to convert # Days to # Business Hours | F11: ='Pricing Details'!B15 -> 0 | G11: ='Pricing Details'!E15 | H11: ='Pricing Details'!AR15 -> 0 | I11: ='Pricing Details'!F15 -> 0 | J11: ='Pricing Details'!AV15 -> 0 | K11: ='Pricing Details'!AU15 -> 0 | M11: ='Pricing Details'!B15 -> 0 | N11: ='Pricing Details'!E15 | O11: ='Pricing Details'!G15 -> 0 | P11: ='Pricing Details'!F15 -> 0 | Q11: ='Pricing Details'!AV15 -> 0 | R11: =O11*Q11 -> 0 | T11: ='Pricing Details'!B15 -> 0 | U11: ='Pricing Details'!E15 | V11: ='Pricing Details'!G15 -> 0 | W11: ='Pricing Details'!H15 -> 0 | X11: ='Pricing Details'!I15 -> 0 | Y11: ='Pricing Details'!J15 -> 0 | Z11: ='Pricing Details'!K15 -> 0 | AA11: ='Pricing Details'!L15 -> 0 | AB11: ='Pricing Details'!M15 -> 0 | AC11: ='Pricing Details'!N15 -> 0 | ... BE11: ='Pricing Details'!AP15 -> 0
A12: Days | B12: Business Hours | F12: ='Pricing Details'!B16 -> 0 | G12: ='Pricing Details'!E16 | H12: ='Pricing Details'!AR16 -> 0 | I12: ='Pricing Details'!F16 -> 0 | J12: ='Pricing Details'!AV16 -> 0 | K12: ='Pricing Details'!AU16 -> 0 | M12: ='Pricing Details'!B16 -> 0 | N12: ='Pricing Details'!E16 | O12: ='Pricing Details'!G16 -> 0 | P12: ='Pricing Details'!F16 -> 0 | Q12: ='Pricing Details'!AV16 -> 0 | R12: =O12*Q12 -> 0 | T12: ='Pricing Details'!B16 -> 0 | U12: ='Pricing Details'!E16 | V12: ='Pricing Details'!G16 -> 0 | W12: ='Pricing Details'!H16 -> 0 | X12: ='Pricing Details'!I16 -> 0 | Y12: ='Pricing Details'!J16 -> 0 | Z12: ='Pricing Details'!K16 -> 0 | AA12: ='Pricing Details'!L16 -> 0 | AB12: ='Pricing Details'!M16 -> 0 | AC12: ='Pricing Details'!N16 -> 0 | ... BE12: ='Pricing Details'!AP16 -> 0
A13: 5 | B13: =A13*8 -> 40 | F13: ='Pricing Details'!B17 -> 0 | G13: ='Pricing Details'!E17 | H13: ='Pricing Details'!AR17 -> 0 | I13: ='Pricing Details'!F17 -> 0 | J13: ='Pricing Details'!AV17 -> 0 | K13: ='Pricing Details'!AU17 -> 0 | M13: ='Pricing Details'!B17 -> 0 | N13: ='Pricing Details'!E17 | O13: ='Pricing Details'!G17 -> 0 | P13: ='Pricing Details'!F17 -> 0 | Q13: ='Pricing Details'!AV17 -> 0 | R13: =O13*Q13 -> 0 | T13: ='Pricing Details'!B17 -> 0 | U13: ='Pricing Details'!E17 | V13: ='Pricing Details'!G17 -> 0 | W13: ='Pricing Details'!H17 -> 0 | X13: ='Pricing Details'!I17 -> 0 | Y13: ='Pricing Details'!J17 -> 0 | Z13: ='Pricing Details'!K17 -> 0 | AA13: ='Pricing Details'!L17 -> 0 | AB13: ='Pricing Details'!M17 -> 0 | AC13: ='Pricing Details'!N17 -> 0 | ... BE13: ='Pricing Details'!AP17 -> 0
A14: 11 | B14: =A14*8 -> 88 | F14: ='Pricing Details'!B18 -> 0 | G14: ='Pricing Details'!E18 | H14: ='Pricing Details'!AR18 -> 0 | I14: ='Pricing Details'!F18 -> 0 | J14: ='Pricing Details'!AV18 -> 0 | K14: ='Pricing Details'!AU18 -> 0 | M14: ='Pricing Details'!B18 -> 0 | N14: ='Pricing Details'!E18 | O14: ='Pricing Details'!G18 -> 0 | P14: ='Pricing Details'!F18 -> 0 | Q14: ='Pricing Details'!AV18 -> 0 | R14: =O14*Q14 -> 0 | T14: ='Pricing Details'!B18 -> 0 | U14: ='Pricing Details'!E18 | V14: ='Pricing Details'!G18 -> 0 | W14: ='Pricing Details'!H18 -> 0 | X14: ='Pricing Details'!I18 -> 0 | Y14: ='Pricing Details'!J18 -> 0 | Z14: ='Pricing Details'!K18 -> 0 | AA14: ='Pricing Details'!L18 -> 0 | AB14: ='Pricing Details'!M18 -> 0 | AC14: ='Pricing Details'!N18 -> 0 | ... BE14: ='Pricing Details'!AP18 -> 0
F15: ='Pricing Details'!B19 -> 0 | G15: ='Pricing Details'!E19 | H15: ='Pricing Details'!AR19 -> 0 | I15: ='Pricing Details'!F19 -> 0 | J15: ='Pricing Details'!AV19 -> 0 | K15: ='Pricing Details'!AU19 -> 0 | M15: ='Pricing Details'!B19 -> 0 | N15: ='Pricing Details'!E19 | O15: ='Pricing Details'!G19 -> 0 | P15: ='Pricing Details'!F19 -> 0 | Q15: ='Pricing Details'!AV19 -> 0 | R15: =O15*Q15 -> 0 | T15: ='Pricing Details'!B19 -> 0 | U15: ='Pricing Details'!E19 | V15: ='Pricing Details'!G19 -> 0 | W15: ='Pricing Details'!H19 -> 0 | X15: ='Pricing Details'!I19 -> 0 | Y15: ='Pricing Details'!J19 -> 0 | Z15: ='Pricing Details'!K19 -> 0 | AA15: ='Pricing Details'!L19 -> 0 | AB15: ='Pricing Details'!M19 -> 0 | AC15: ='Pricing Details'!N19 -> 0 | ... BE15: ='Pricing Details'!AP19 -> 0
A16: Use to input the actual Contractor Cost (what we are paying the contractor) | C16: To change you need permission from Havagi | D16: Enter the Net Margin % you want to achieve for this role | F16: ='Pricing Details'!B20 -> 0 | G16: ='Pricing Details'!E20 | H16: ='Pricing Details'!AR20 -> 0 | I16: ='Pricing Details'!F20 -> 0 | J16: ='Pricing Details'!AV20 -> 0 | K16: ='Pricing Details'!AU20 -> 0 | M16: ='Pricing Details'!B20 -> 0 | N16: ='Pricing Details'!E20 | O16: ='Pricing Details'!G20 -> 0 | P16: ='Pricing Details'!F20 -> 0 | Q16: ='Pricing Details'!AV20 -> 0 | R16: =O16*Q16 -> 0 | T16: ='Pricing Details'!B20 -> 0 | U16: ='Pricing Details'!E20 | V16: ='Pricing Details'!G20 -> 0 | W16: ='Pricing Details'!H20 -> 0 | X16: ='Pricing Details'!I20 -> 0 | Y16: ='Pricing Details'!J20 -> 0 | Z16: ='Pricing Details'!K20 -> 0 | AA16: ='Pricing Details'!L20 -> 0 | AB16: ='Pricing Details'!M20 -> 0 | AC16: ='Pricing Details'!N20 -> 0 | ... BE16: ='Pricing Details'!AP20 -> 0
A17: Contractor | B17: Hourly Cost | C17: OpX Hourly | D17: Net Margin % | F17: ='Pricing Details'!B21 -> 0 | G17: ='Pricing Details'!E21 | H17: ='Pricing Details'!AR21 -> 0 | I17: ='Pricing Details'!F21 -> 0 | J17: ='Pricing Details'!AV21 -> 0 | K17: ='Pricing Details'!AU21 -> 0 | M17: ='Pricing Details'!B21 -> 0 | N17: ='Pricing Details'!E21 | O17: ='Pricing Details'!G21 -> 0 | P17: ='Pricing Details'!F21 -> 0 | Q17: ='Pricing Details'!AV21 -> 0 | R17: =O17*Q17 -> 0 | T17: ='Pricing Details'!B21 -> 0 | U17: ='Pricing Details'!E21 | V17: ='Pricing Details'!G21 -> 0 | W17: ='Pricing Details'!H21 -> 0 | X17: ='Pricing Details'!I21 -> 0 | Y17: ='Pricing Details'!J21 -> 0 | Z17: ='Pricing Details'!K21 -> 0 | AA17: ='Pricing Details'!L21 -> 0 | AB17: ='Pricing Details'!M21 -> 0 | AC17: ='Pricing Details'!N21 -> 0 | ... BE17: ='Pricing Details'!AP21 -> 0
A18: Contractor 1 | B18: 100 | C18: 45 | D18: 0.35 | F18: ='Pricing Details'!B22 -> 0 | G18: ='Pricing Details'!E22 | H18: ='Pricing Details'!AR22 -> 0 | I18: ='Pricing Details'!F22 -> 0 | J18: ='Pricing Details'!AV22 -> 0 | K18: ='Pricing Details'!AU22 -> 0 | M18: ='Pricing Details'!B22 -> 0 | N18: ='Pricing Details'!E22 | O18: ='Pricing Details'!G22 -> 0 | P18: ='Pricing Details'!F22 -> 0 | Q18: ='Pricing Details'!AV22 -> 0 | R18: =O18*Q18 -> 0 | T18: ='Pricing Details'!B22 -> 0 | U18: ='Pricing Details'!E22 | V18: ='Pricing Details'!G22 -> 0 | W18: ='Pricing Details'!H22 -> 0 | X18: ='Pricing Details'!I22 -> 0 | Y18: ='Pricing Details'!J22 -> 0 | Z18: ='Pricing Details'!K22 -> 0 | AA18: ='Pricing Details'!L22 -> 0 | AB18: ='Pricing Details'!M22 -> 0 | AC18: ='Pricing Details'!N22 -> 0 | ... BE18: ='Pricing Details'!AP22 -> 0
A19: Contractor 2 | B19: 100 | C19: 45 | D19: 0.35 | F19: ='Pricing Details'!B23 -> 0 | G19: ='Pricing Details'!E23 | H19: ='Pricing Details'!AR23 -> 0 | I19: ='Pricing Details'!F23 -> 0 | J19: ='Pricing Details'!AV23 -> 0 | K19: ='Pricing Details'!AU23 -> 0 | M19: ='Pricing Details'!B23 -> 0 | N19: ='Pricing Details'!E23 | O19: ='Pricing Details'!G23 -> 0 | P19: ='Pricing Details'!F23 -> 0 | Q19: ='Pricing Details'!AV23 -> 0 | R19: =O19*Q19 -> 0 | T19: ='Pricing Details'!B23 -> 0 | U19: ='Pricing Details'!E23 | V19: ='Pricing Details'!G23 -> 0 | W19: ='Pricing Details'!H23 -> 0 | X19: ='Pricing Details'!I23 -> 0 | Y19: ='Pricing Details'!J23 -> 0 | Z19: ='Pricing Details'!K23 -> 0 | AA19: ='Pricing Details'!L23 -> 0 | AB19: ='Pricing Details'!M23 -> 0 | AC19: ='Pricing Details'!N23 -> 0 | ... BE19: ='Pricing Details'!AP23 -> 0
A20: Contractor 3 | B20: 100 | C20: 45 | D20: 0.35 | F20: ='Pricing Details'!B24 -> 0 | G20: ='Pricing Details'!E24 | H20: ='Pricing Details'!AR24 -> 0 | I20: ='Pricing Details'!F24 -> 0 | J20: ='Pricing Details'!AV24 -> 0 | K20: ='Pricing Details'!AU24 -> 0 | M20: ='Pricing Details'!B24 -> 0 | N20: ='Pricing Details'!E24 | O20: ='Pricing Details'!G24 -> 0 | P20: ='Pricing Details'!F24 -> 0 | Q20: ='Pricing Details'!AV24 -> 0 | R20: =O20*Q20 -> 0 | T20: ='Pricing Details'!B24 -> 0 | U20: ='Pricing Details'!E24 | V20: ='Pricing Details'!G24 -> 0 | W20: ='Pricing Details'!H24 -> 0 | X20: ='Pricing Details'!I24 -> 0 | Y20: ='Pricing Details'!J24 -> 0 | Z20: ='Pricing Details'!K24 -> 0 | AA20: ='Pricing Details'!L24 -> 0 | AB20: ='Pricing Details'!M24 -> 0 | AC20: ='Pricing Details'!N24 -> 0 | ... BE20: ='Pricing Details'!AP24 -> 0
A21: Contractor 4 | B21: 100 | C21: 45 | D21: 0.35 | F21: ='Pricing Details'!B25 -> 0 | G21: ='Pricing Details'!E25 | H21: ='Pricing Details'!AR25 -> 0 | I21: ='Pricing Details'!F25 -> 0 | J21: ='Pricing Details'!AV25 -> 0 | K21: ='Pricing Details'!AU25 -> 0 | M21: ='Pricing Details'!B25 -> 0 | N21: ='Pricing Details'!E25 | O21: ='Pricing Details'!G25 -> 0 | P21: ='Pricing Details'!F25 -> 0 | Q21: ='Pricing Details'!AV25 -> 0 | R21: =O21*Q21 -> 0 | T21: ='Pricing Details'!B25 -> 0 | U21: ='Pricing Details'!E25 | V21: ='Pricing Details'!G25 -> 0 | W21: ='Pricing Details'!H25 -> 0 | X21: ='Pricing Details'!I25 -> 0 | Y21: ='Pricing Details'!J25 -> 0 | Z21: ='Pricing Details'!K25 -> 0 | AA21: ='Pricing Details'!L25 -> 0 | AB21: ='Pricing Details'!M25 -> 0 | AC21: ='Pricing Details'!N25 -> 0 | ... BE21: ='Pricing Details'!AP25 -> 0
A22: Contractor 5 | B22: 100 | C22: 45 | D22: 0.35 | F22: ='Pricing Details'!B26 -> 0 | G22: ='Pricing Details'!E26 | H22: ='Pricing Details'!AR26 -> 0 | I22: ='Pricing Details'!F26 -> 0 | J22: ='Pricing Details'!AV26 -> 0 | K22: ='Pricing Details'!AU26 -> 0 | M22: ='Pricing Details'!B26 -> 0 | N22: ='Pricing Details'!E26 | O22: ='Pricing Details'!G26 -> 0 | P22: ='Pricing Details'!F26 -> 0 | Q22: ='Pricing Details'!AV26 -> 0 | R22: =O22*Q22 -> 0 | T22: ='Pricing Details'!B26 -> 0 | U22: ='Pricing Details'!E26 | V22: ='Pricing Details'!G26 -> 0 | W22: ='Pricing Details'!H26 -> 0 | X22: ='Pricing Details'!I26 -> 0 | Y22: ='Pricing Details'!J26 -> 0 | Z22: ='Pricing Details'!K26 -> 0 | AA22: ='Pricing Details'!L26 -> 0 | AB22: ='Pricing Details'!M26 -> 0 | AC22: ='Pricing Details'!N26 -> 0 | ... BE22: ='Pricing Details'!AP26 -> 0
F23: ='Pricing Details'!B27 -> 0 | G23: ='Pricing Details'!E27 | H23: ='Pricing Details'!AR27 -> 0 | I23: ='Pricing Details'!F27 -> 0 | J23: ='Pricing Details'!AV27 -> 0 | K23: ='Pricing Details'!AU27 -> 0 | M23: ='Pricing Details'!B27 -> 0 | N23: ='Pricing Details'!E27 | O23: ='Pricing Details'!G27 -> 0 | P23: ='Pricing Details'!F27 -> 0 | Q23: ='Pricing Details'!AV27 -> 0 | R23: =O23*Q23 -> 0 | T23: ='Pricing Details'!B27 -> 0 | U23: ='Pricing Details'!E27 | V23: ='Pricing Details'!G27 -> 0 | W23: ='Pricing Details'!H27 -> 0 | X23: ='Pricing Details'!I27 -> 0 | Y23: ='Pricing Details'!J27 -> 0 | Z23: ='Pricing Details'!K27 -> 0 | AA23: ='Pricing Details'!L27 -> 0 | AB23: ='Pricing Details'!M27 -> 0 | AC23: ='Pricing Details'!N27 -> 0 | ... BE23: ='Pricing Details'!AP27 -> 0
A24: Use to back into the Net Margin % when you have the hourly bill rate | F24: ='Pricing Details'!B28 -> 0 | G24: ='Pricing Details'!E28 | H24: ='Pricing Details'!AR28 -> 0 | I24: ='Pricing Details'!F28 -> 0 | J24: ='Pricing Details'!AV28 -> 0 | K24: ='Pricing Details'!AU28 -> 0 | M24: ='Pricing Details'!B28 -> 0 | N24: ='Pricing Details'!E28 | O24: ='Pricing Details'!G28 -> 0 | P24: ='Pricing Details'!F28 -> 0 | Q24: ='Pricing Details'!AV28 -> 0 | R24: =O24*Q24 -> 0 | T24: ='Pricing Details'!B28 -> 0 | U24: ='Pricing Details'!E28 | V24: ='Pricing Details'!G28 -> 0 | W24: ='Pricing Details'!H28 -> 0 | X24: ='Pricing Details'!I28 -> 0 | Y24: ='Pricing Details'!J28 -> 0 | Z24: ='Pricing Details'!K28 -> 0 | AA24: ='Pricing Details'!L28 -> 0 | AB24: ='Pricing Details'!M28 -> 0 | AC24: ='Pricing Details'!N28 -> 0 | ... BE24: ='Pricing Details'!AP28 -> 0
A25: Goal Hourly Rate | B25: Contractor Hourly Cost + OpX Cost | C25: Net Margin % | F25: ='Pricing Details'!B29 -> 0 | G25: ='Pricing Details'!E29 | H25: ='Pricing Details'!AR29 -> 0 | I25: ='Pricing Details'!F29 -> 0 | J25: ='Pricing Details'!AV29 -> 0 | K25: ='Pricing Details'!AU29 -> 0 | M25: ='Pricing Details'!B29 -> 0 | N25: ='Pricing Details'!E29 | O25: ='Pricing Details'!G29 -> 0 | P25: ='Pricing Details'!F29 -> 0 | Q25: ='Pricing Details'!AV29 -> 0 | R25: =O25*Q25 -> 0 | T25: ='Pricing Details'!B29 -> 0 | U25: ='Pricing Details'!E29 | V25: ='Pricing Details'!G29 -> 0 | W25: ='Pricing Details'!H29 -> 0 | X25: ='Pricing Details'!I29 -> 0 | Y25: ='Pricing Details'!J29 -> 0 | Z25: ='Pricing Details'!K29 -> 0 | AA25: ='Pricing Details'!L29 -> 0 | AB25: ='Pricing Details'!M29 -> 0 | AC25: ='Pricing Details'!N29 -> 0 | ... BE25: ='Pricing Details'!AP29 -> 0
A26: 185 | B26: 120 | C26: =(A26-B26)/A26 -> 0.35135135 | F26: ='Pricing Details'!B30 -> 0 | G26: ='Pricing Details'!E30 | H26: ='Pricing Details'!AR30 -> 0 | I26: ='Pricing Details'!F30 -> 0 | J26: ='Pricing Details'!AV30 -> 0 | K26: ='Pricing Details'!AU30 -> 0 | M26: ='Pricing Details'!B30 -> 0 | N26: ='Pricing Details'!E30 | O26: ='Pricing Details'!G30 -> 0 | P26: ='Pricing Details'!F30 -> 0 | Q26: ='Pricing Details'!AV30 -> 0 | R26: =O26*Q26 -> 0 | T26: ='Pricing Details'!B30 -> 0 | U26: ='Pricing Details'!E30 | V26: ='Pricing Details'!G30 -> 0 | W26: ='Pricing Details'!H30 -> 0 | X26: ='Pricing Details'!I30 -> 0 | Y26: ='Pricing Details'!J30 -> 0 | Z26: ='Pricing Details'!K30 -> 0 | AA26: ='Pricing Details'!L30 -> 0 | AB26: ='Pricing Details'!M30 -> 0 | AC26: ='Pricing Details'!N30 -> 0 | ... BE26: ='Pricing Details'!AP30 -> 0
F27: ='Pricing Details'!B31 -> 0 | G27: ='Pricing Details'!E31 | H27: ='Pricing Details'!AR31 -> 0 | I27: ='Pricing Details'!F31 -> 0 | J27: ='Pricing Details'!AV31 -> 0 | K27: ='Pricing Details'!AU31 -> 0 | M27: ='Pricing Details'!B31 -> 0 | N27: ='Pricing Details'!E31 | O27: ='Pricing Details'!G31 -> 0 | P27: ='Pricing Details'!F31 -> 0 | Q27: ='Pricing Details'!AV31 -> 0 | R27: =O27*Q27 -> 0 | T27: ='Pricing Details'!B31 -> 0 | U27: ='Pricing Details'!E31 | V27: ='Pricing Details'!G31 -> 0 | W27: ='Pricing Details'!H31 -> 0 | X27: ='Pricing Details'!I31 -> 0 | Y27: ='Pricing Details'!J31 -> 0 | Z27: ='Pricing Details'!K31 -> 0 | AA27: ='Pricing Details'!L31 -> 0 | AB27: ='Pricing Details'!M31 -> 0 | AC27: ='Pricing Details'!N31 -> 0 | ... BE27: ='Pricing Details'!AP31 -> 0
A28: Below is the standard price. If you are billing each month, then put 1 hour in each month. The price can be discounted using the Hourly Rate or Bottom Line Discount. | F28: ='Pricing Details'!B32 -> 0 | G28: ='Pricing Details'!E32 | H28: ='Pricing Details'!AR32 -> 0 | I28: ='Pricing Details'!F32 -> 0 | J28: ='Pricing Details'!AV32 -> 0 | K28: ='Pricing Details'!AU32 -> 0 | M28: ='Pricing Details'!B32 -> 0 | N28: ='Pricing Details'!E32 | O28: ='Pricing Details'!G32 -> 0 | P28: ='Pricing Details'!F32 -> 0 | Q28: ='Pricing Details'!AV32 -> 0 | R28: =O28*Q28 -> 0 | T28: ='Pricing Details'!B32 -> 0 | U28: ='Pricing Details'!E32 | V28: ='Pricing Details'!G32 -> 0 | W28: ='Pricing Details'!H32 -> 0 | X28: ='Pricing Details'!I32 -> 0 | Y28: ='Pricing Details'!J32 -> 0 | Z28: ='Pricing Details'!K32 -> 0 | AA28: ='Pricing Details'!L32 -> 0 | AB28: ='Pricing Details'!M32 -> 0 | AC28: ='Pricing Details'!N32 -> 0 | ... BE28: ='Pricing Details'!AP32 -> 0
F29: ='Pricing Details'!B33 -> 0 | G29: ='Pricing Details'!E33 | H29: ='Pricing Details'!AR33 -> 0 | I29: ='Pricing Details'!F33 -> 0 | J29: ='Pricing Details'!AV33 -> 0 | K29: ='Pricing Details'!AU33 -> 0 | M29: ='Pricing Details'!B33 -> 0 | N29: ='Pricing Details'!E33 | O29: ='Pricing Details'!G33 -> 0 | P29: ='Pricing Details'!F33 -> 0 | Q29: ='Pricing Details'!AV33 -> 0 | R29: =O29*Q29 -> 0 | T29: ='Pricing Details'!B33 -> 0 | U29: ='Pricing Details'!E33 | V29: ='Pricing Details'!G33 -> 0 | W29: ='Pricing Details'!H33 -> 0 | X29: ='Pricing Details'!I33 -> 0 | Y29: ='Pricing Details'!J33 -> 0 | Z29: ='Pricing Details'!K33 -> 0 | AA29: ='Pricing Details'!L33 -> 0 | AB29: ='Pricing Details'!M33 -> 0 | AC29: ='Pricing Details'!N33 -> 0 | ... BE29: ='Pricing Details'!AP33 -> 0
A30: Donyati Product | B30: Hourly Price | F30: ='Pricing Details'!B34 -> 0 | G30: ='Pricing Details'!E34 | H30: ='Pricing Details'!AR34 -> 0 | I30: ='Pricing Details'!F34 -> 0 | J30: ='Pricing Details'!AV34 -> 0 | K30: ='Pricing Details'!AU34 -> 0 | M30: ='Pricing Details'!B34 -> 0 | N30: ='Pricing Details'!E34 | O30: ='Pricing Details'!G34 -> 0 | P30: ='Pricing Details'!F34 -> 0 | Q30: ='Pricing Details'!AV34 -> 0 | R30: =O30*Q30 -> 0 | T30: ='Pricing Details'!B34 -> 0 | U30: ='Pricing Details'!E34 | V30: ='Pricing Details'!G34 -> 0 | W30: ='Pricing Details'!H34 -> 0 | X30: ='Pricing Details'!I34 -> 0 | Y30: ='Pricing Details'!J34 -> 0 | Z30: ='Pricing Details'!K34 -> 0 | AA30: ='Pricing Details'!L34 -> 0 | AB30: ='Pricing Details'!M34 -> 0 | AC30: ='Pricing Details'!N34 -> 0 | ... BE30: ='Pricing Details'!AP34 -> 0
A31: DART | B31: 4000 | F31: ='Pricing Details'!B35 -> 0 | G31: ='Pricing Details'!E35 | H31: ='Pricing Details'!AR35 -> 0 | I31: ='Pricing Details'!F35 -> 0 | J31: ='Pricing Details'!AV35 -> 0 | K31: ='Pricing Details'!AU35 -> 0 | M31: ='Pricing Details'!B35 -> 0 | N31: ='Pricing Details'!E35 | O31: ='Pricing Details'!G35 -> 0 | P31: ='Pricing Details'!F35 -> 0 | Q31: ='Pricing Details'!AV35 -> 0 | R31: =O31*Q31 -> 0 | T31: ='Pricing Details'!B35 -> 0 | U31: ='Pricing Details'!E35 | V31: ='Pricing Details'!G35 -> 0 | W31: ='Pricing Details'!H35 -> 0 | X31: ='Pricing Details'!I35 -> 0 | Y31: ='Pricing Details'!J35 -> 0 | Z31: ='Pricing Details'!K35 -> 0 | AA31: ='Pricing Details'!L35 -> 0 | AB31: ='Pricing Details'!M35 -> 0 | AC31: ='Pricing Details'!N35 -> 0 | ... BE31: ='Pricing Details'!AP35 -> 0
A32: EPM Cloud Assurance | B32: 4000 | F32: ='Pricing Details'!B36 -> 0 | G32: ='Pricing Details'!E36 | H32: ='Pricing Details'!AR36 -> 0 | I32: ='Pricing Details'!F36 -> 0 | J32: ='Pricing Details'!AV36 -> 0 | K32: ='Pricing Details'!AU36 -> 0 | M32: ='Pricing Details'!B36 -> 0 | N32: ='Pricing Details'!E36 | O32: ='Pricing Details'!G36 -> 0 | P32: ='Pricing Details'!F36 -> 0 | Q32: ='Pricing Details'!AV36 -> 0 | R32: =O32*Q32 -> 0 | T32: ='Pricing Details'!B36 -> 0 | U32: ='Pricing Details'!E36 | V32: ='Pricing Details'!G36 -> 0 | W32: ='Pricing Details'!H36 -> 0 | X32: ='Pricing Details'!I36 -> 0 | Y32: ='Pricing Details'!J36 -> 0 | Z32: ='Pricing Details'!K36 -> 0 | AA32: ='Pricing Details'!L36 -> 0 | AB32: ='Pricing Details'!M36 -> 0 | AC32: ='Pricing Details'!N36 -> 0 | ... BE32: ='Pricing Details'!AP36 -> 0
F33: ='Pricing Details'!B37 -> 0 | G33: ='Pricing Details'!E37 | H33: ='Pricing Details'!AR37 -> 0 | I33: ='Pricing Details'!F37 -> 0 | J33: ='Pricing Details'!AV37 -> 0 | K33: ='Pricing Details'!AU37 -> 0 | M33: ='Pricing Details'!B37 -> 0 | N33: ='Pricing Details'!E37 | O33: ='Pricing Details'!G37 -> 0 | P33: ='Pricing Details'!F37 -> 0 | Q33: ='Pricing Details'!AV37 -> 0 | R33: =O33*Q33 -> 0 | T33: ='Pricing Details'!B37 -> 0 | U33: ='Pricing Details'!E37 | V33: ='Pricing Details'!G37 -> 0 | W33: ='Pricing Details'!H37 -> 0 | X33: ='Pricing Details'!I37 -> 0 | Y33: ='Pricing Details'!J37 -> 0 | Z33: ='Pricing Details'!K37 -> 0 | AA33: ='Pricing Details'!L37 -> 0 | AB33: ='Pricing Details'!M37 -> 0 | AC33: ='Pricing Details'!N37 -> 0 | ... BE33: ='Pricing Details'!AP37 -> 0
F34: ='Pricing Details'!B38 -> 0 | G34: ='Pricing Details'!E38 | H34: ='Pricing Details'!AR38 -> 0 | I34: ='Pricing Details'!F38 -> 0 | J34: ='Pricing Details'!AV38 -> 0 | K34: ='Pricing Details'!AU38 -> 0 | M34: ='Pricing Details'!B38 -> 0 | N34: ='Pricing Details'!E38 | O34: ='Pricing Details'!G38 -> 0 | P34: ='Pricing Details'!F38 -> 0 | Q34: ='Pricing Details'!AV38 -> 0 | R34: =O34*Q34 -> 0 | T34: ='Pricing Details'!B38 -> 0 | U34: ='Pricing Details'!E38 | V34: ='Pricing Details'!G38 -> 0 | W34: ='Pricing Details'!H38 -> 0 | X34: ='Pricing Details'!I38 -> 0 | Y34: ='Pricing Details'!J38 -> 0 | Z34: ='Pricing Details'!K38 -> 0 | AA34: ='Pricing Details'!L38 -> 0 | AB34: ='Pricing Details'!M38 -> 0 | AC34: ='Pricing Details'!N38 -> 0 | ... BE34: ='Pricing Details'!AP38 -> 0
F35: ='Pricing Details'!B39 -> 0 | G35: ='Pricing Details'!E39 | H35: ='Pricing Details'!AR39 -> 0 | I35: ='Pricing Details'!F39 -> 0 | J35: ='Pricing Details'!AV39 -> 0 | K35: ='Pricing Details'!AU39 -> 0 | M35: ='Pricing Details'!B39 -> 0 | N35: ='Pricing Details'!E39 | O35: ='Pricing Details'!G39 -> 0 | P35: ='Pricing Details'!F39 -> 0 | Q35: ='Pricing Details'!AV39 -> 0 | R35: =O35*Q35 -> 0 | T35: ='Pricing Details'!B39 -> 0 | U35: ='Pricing Details'!E39 | V35: ='Pricing Details'!G39 -> 0 | W35: ='Pricing Details'!H39 -> 0 | X35: ='Pricing Details'!I39 -> 0 | Y35: ='Pricing Details'!J39 -> 0 | Z35: ='Pricing Details'!K39 -> 0 | AA35: ='Pricing Details'!L39 -> 0 | AB35: ='Pricing Details'!M39 -> 0 | AC35: ='Pricing Details'!N39 -> 0 | ... BE35: ='Pricing Details'!AP39 -> 0
F36: ='Pricing Details'!B40 -> 0 | G36: ='Pricing Details'!E40 | H36: ='Pricing Details'!AR40 -> 0 | I36: ='Pricing Details'!F40 -> 0 | J36: ='Pricing Details'!AV40 -> 0 | K36: ='Pricing Details'!AU40 -> 0 | M36: ='Pricing Details'!B40 -> 0 | N36: ='Pricing Details'!E40 | O36: ='Pricing Details'!G40 -> 0 | P36: ='Pricing Details'!F40 -> 0 | Q36: ='Pricing Details'!AV40 -> 0 | R36: =O36*Q36 -> 0 | T36: ='Pricing Details'!B40 -> 0 | U36: ='Pricing Details'!E40 | V36: ='Pricing Details'!G40 -> 0 | W36: ='Pricing Details'!H40 -> 0 | X36: ='Pricing Details'!I40 -> 0 | Y36: ='Pricing Details'!J40 -> 0 | Z36: ='Pricing Details'!K40 -> 0 | AA36: ='Pricing Details'!L40 -> 0 | AB36: ='Pricing Details'!M40 -> 0 | AC36: ='Pricing Details'!N40 -> 0 | ... BE36: ='Pricing Details'!AP40 -> 0
F37: ='Pricing Details'!B41 -> 0 | G37: ='Pricing Details'!E41 | H37: ='Pricing Details'!AR41 -> 0 | I37: ='Pricing Details'!F41 -> 0 | J37: ='Pricing Details'!AV41 -> 0 | K37: ='Pricing Details'!AU41 -> 0 | M37: ='Pricing Details'!B41 -> 0 | N37: ='Pricing Details'!E41 | O37: ='Pricing Details'!G41 -> 0 | P37: ='Pricing Details'!F41 -> 0 | Q37: ='Pricing Details'!AV41 -> 0 | R37: =O37*Q37 -> 0 | T37: ='Pricing Details'!B41 -> 0 | U37: ='Pricing Details'!E41 | V37: ='Pricing Details'!G41 -> 0 | W37: ='Pricing Details'!H41 -> 0 | X37: ='Pricing Details'!I41 -> 0 | Y37: ='Pricing Details'!J41 -> 0 | Z37: ='Pricing Details'!K41 -> 0 | AA37: ='Pricing Details'!L41 -> 0 | AB37: ='Pricing Details'!M41 -> 0 | AC37: ='Pricing Details'!N41 -> 0 | ... BE37: ='Pricing Details'!AP41 -> 0
F38: ='Pricing Details'!B42 -> 0 | G38: ='Pricing Details'!E42 | H38: ='Pricing Details'!AR42 -> 0 | I38: ='Pricing Details'!F42 -> 0 | J38: ='Pricing Details'!AV42 -> 0 | K38: ='Pricing Details'!AU42 -> 0 | M38: ='Pricing Details'!B42 -> 0 | N38: ='Pricing Details'!E42 | O38: ='Pricing Details'!G42 -> 0 | P38: ='Pricing Details'!F42 -> 0 | Q38: ='Pricing Details'!AV42 -> 0 | R38: =O38*Q38 -> 0 | T38: ='Pricing Details'!B42 -> 0 | U38: ='Pricing Details'!E42 | V38: ='Pricing Details'!G42 -> 0 | W38: ='Pricing Details'!H42 -> 0 | X38: ='Pricing Details'!I42 -> 0 | Y38: ='Pricing Details'!J42 -> 0 | Z38: ='Pricing Details'!K42 -> 0 | AA38: ='Pricing Details'!L42 -> 0 | AB38: ='Pricing Details'!M42 -> 0 | AC38: ='Pricing Details'!N42 -> 0 | ... BE38: ='Pricing Details'!AP42 -> 0
F39: ='Pricing Details'!B43 -> 0 | G39: ='Pricing Details'!E43 | H39: ='Pricing Details'!AR43 -> 0 | I39: ='Pricing Details'!F43 -> 0 | J39: ='Pricing Details'!AV43 -> 0 | K39: ='Pricing Details'!AU43 -> 0 | M39: ='Pricing Details'!B43 -> 0 | N39: ='Pricing Details'!E43 | O39: ='Pricing Details'!G43 -> 0 | P39: ='Pricing Details'!F43 -> 0 | Q39: ='Pricing Details'!AV43 -> 0 | R39: =O39*Q39 -> 0 | T39: ='Pricing Details'!B43 -> 0 | U39: ='Pricing Details'!E43 | V39: ='Pricing Details'!G43 -> 0 | W39: ='Pricing Details'!H43 -> 0 | X39: ='Pricing Details'!I43 -> 0 | Y39: ='Pricing Details'!J43 -> 0 | Z39: ='Pricing Details'!K43 -> 0 | AA39: ='Pricing Details'!L43 -> 0 | AB39: ='Pricing Details'!M43 -> 0 | AC39: ='Pricing Details'!N43 -> 0 | ... BE39: ='Pricing Details'!AP43 -> 0
H40: =SUM(H5:H39) -> 310 | K40: =SUM(K5:K39) -> 71300 | O40: =SUM(O5:O39) -> 50 | Q40: Monthly | R40: =SUM(R5:R39) -> 11500
...

Sheet Resource List
A1: Practice | B1: Role | C1: Name | D1: Updated 11/11/2025
A2: Cloud_Practice_USA | B2: Program Manager | C2: Rodrigo Farinazo
A3: Cloud_Practice_USA | B3: Program Manager | C3: Michael Stevens
A4: Cloud_Practice_USA | B4: Sr. Program Lead | C4: Michael J Meier
A5: Cloud_Practice_USA | B5: Project Manager | C5: Kerri Dittmar
A6: Cloud_Practice_USA | B6: Engineer | C6: Harrison Koons
A7: Cloud_Practice_USA | B7: Program Lead | C7: Evan C List
A8: Cloud_Practice_USA | B8: Architect | C8: Christina Allan
A9: Cloud_Practice_USA | B9: Architect | C9: Brandon C Wagoner
A10: Cloud_Practice_USA | B10: Architect | C10: Eric Paul
A11: Cloud_Practice_USA | B11: Architect | C11: Sean Clark
A12: Cloud_Practice_USA | B12: Engineer | C12: Asha Angalla
A13: Cloud_Practice_USA | B13: Engineer | C13: Gowtham Nelavelli
... A277: TS_Practice_USA | B277: Business/Data Analyst | C277: Jinali Kamdar

Sheet Timeline 36 Weeks
G1: Week 1 Date is the Monday of the week of the Project Start Date on the Pricing Sheet tab
G2: Timeline in Weeks
B4: Week # | C4: 1 | D4: =C4+1 -> 2 | E4: =D4+1 -> 3 | F4: 4 | G4: 5 | H4: 6 | I4: 7 | J4: 8 | K4: 9 | L4: 10 | M4: 11 | N4: 12 | O4: 13 | P4: 14 | Q4: 15 | R4: 16 | S4: =R4+1 -> 17 | T4: =S4+1 -> 18 | U4: =T4+1 -> 19 | V4: =U4+1 -> 20 | W4: =V4+1 -> 21 | X4: =W4+1 -> 22 | Y4: =X4+1 -> 23 | Z4: =Y4+1 -> 24 | ... AP4: =AO4+1 -> 40
B5: Project Phases | C5: =('Pricing Details'!F4)-WEEKDAY('Pricing Details'!F4,3) -> 46055 | D5: =C5+7 -> 46062 | E5: =D5+7 -> 46069 | F5: =E5+7 -> 46076 | G5: =F5+7 -> 46083 | H5: =G5+7 -> 46090 | I5: =H5+7 -> 46097 | J5: =I5+7 -> 46104 | K5: =J5+7 -> 46111 | ... AP5: =AO5+7 -> 46328
B6: Mobilize | C6: 1
B7: Requirements | D7: 3
B8: Design | G8: 5
B9: Application Build / Unit Testing | L9: 12
B10: Data Integrations | J10: 14
B11: Report Build | R11: 6
B12: Performance Testing Prep & Execution | W12: 2
B13: SIT Prep | Y13: 1
B14: SIT Execute & Remediate | Z14: 2
B15: UAT Prep | AB15: 1
B16: UAT Execute & Remediate | AC16: 2
B17: Training Prep | AE17: 2
B18: Training Delivery | AG18: 1
B19: Data Validation | Q19: Reconciliation / Client sign-off
B20: Parallel #1 | AH20: 2
B21: Parallel #2 | AJ21: 2
B22: Go Live | AL22: 1
B23: Post Production Support / Hypercare | AM23: 2
B24: Holidays
B27: Project Manager (FTE combine US / India) | C27: 40 | D27: 40 | E27: 40 | F27: 40 | G27: 40 | H27: 40 | I27: 40 | J27: 40 | K27: 40 | L27: 40 | M27: 40 | N27: 40 | O27: 40 | P27: 40 | Q27: 40 | R27: 40 | S27: 40 | T27: 40 | U27: 40 | V27: 40 | W27: 40 | X27: 40 | Y27: 40 | Z27: 40 | AA27: 40 | AB27: 40 | AC27: 40 | AD27: 40 | AE27: 40 | AF27: 40 | AG27: 40 | AH27: 40 | AI27: 40 | AJ27: 40 | AK27: 40 | AL27: 40
B28: Architect | C28: 24 | D28: 36 | E28: 36 | F28: 36 | G28: 36 | H28: 36 | I28: 36 | J28: 36 | K28: 36 | L28: 24 | M28: 24 | N28: 16 | O28: 8 | P28: 8 | Q28: 8 | R28: 8 | S28: 8 | T28: 8 | U28: 8 | V28: 8 | W28: 8 | X28: 16 | Y28: 16 | Z28: 16 | AA28: 16 | AB28: 16 | AC28: 16 | AD28: 16
B29: FCC / Planning Lead Developer (US) | C29: 40 | D29: 40 | E29: 40 | F29: 40 | G29: 40 | H29: 40 | I29: 40 | J29: 40 | K29: 40 | L29: 40 | M29: 40 | N29: 40 | O29: 40 | P29: 40 | Q29: 40 | R29: 40 | S29: 40 | T29: 40 | U29: 40 | V29: 40 | W29: 40 | X29: 40 | Y29: 40 | Z29: 40 | AA29: 40 | AB29: 40 | AC29: 40 | AD29: 40 | AE29: 40 | AF29: 40 | AG29: 40 | AH29: 40 | AI29: 40 | AJ29: 40 | AK29: 40 | AL29: 40 | AM29: 40 | AN29: 40
B30: FCC / Planning Developer (India) | K30: 40 | L30: 40 | M30: 40 | N30: 40 | O30: 40 | P30: 40 | Q30: 40 | R30: 40 | S30: 40 | T30: 40 | U30: 40 | V30: 40 | W30: 40 | X30: 40 | Y30: 40 | Z30: 40 | AA30: 40 | AB30: 40 | AC30: 40 | AD30: 40 | AE30: 40 | AF30: 40 | AG30: 40 | AH30: 40 | AI30: 40 | AJ30: 40 | AK30: 40 | AL30: 40 | AM30: 40 | AN30: 40
B31: Data Integration Lead Developer (US) | I31: 40 | J31: 40 | K31: 40 | L31: 40 | M31: 40 | N31: 40 | O31: 40 | P31: 16 | Q31: 16 | R31: 16 | S31: 16 | T31: 16 | U31: 16 | V31: 16 | W31: 16 | X31: 16 | Y31: 36 | Z31: 36 | AA31: 36 | AB31: 16 | AC31: 24 | AD31: 24 | AE31: 8 | AF31: 8 | AG31: 8 | AH31: 8 | AI31: 8 | AJ31: 8 | AK31: 8 | AL31: 8
B32: Data Integration Developer (India) | K32: 40 | L32: 40 | M32: 40 | N32: 40 | O32: 40 | P32: 40 | Q32: 40 | R32: 40 | S32: 40 | T32: 40 | U32: 40 | V32: 40 | W32: 40 | X32: 40 | Y32: 40 | Z32: 40 | AA32: 40 | AB32: 40 | AC32: 40 | AD32: 40 | AE32: 40 | AF32: 40 | AG32: 40 | AH32: 40 | AI32: 40 | AJ32: 40 | AK32: 40 | AL32: 40 | AM32: 40 | AN32: 40
B33: Narrative Reporting Lead | R33: 40 | S33: 40 | T33: 40 | U33: 40 | V33: 40 | W33: 40

Sheet Deliverables 
A1: Mobilize | B1: Requirements | C1: Design | D1: Build | E1: Testing | F1: Training | G1: Parallel Testing | H1: HyperCare
A3: 1. Program Objective | B3: 1. Scope Alignment & Requirements Preparation | C3: 1. Design Sessions for Requirements | D3: 1. Application Development & Unit Testing | E3: 1. Performance Testing | F3: 1. Train-the-Trainer | G3: 1. Parallel Test support (required for FCC | optional for Planning) | H3: 1. Production Support
A4: Vision & Goals | B4: Conduct a scoping session to determine immediate needs and long-term goals. | C4: Current state process review | D4: Dimensions, members, primary hiearhies and alternate hierarchies | E4: Performance expections / benchmarks | F4: Training Guides | G4: Client led non-quarter end close | Donyati support
A5: Challenges & Priorities | B5: Gather Requirements for desired end state processes | C5: Conduct design workshops to flesh-out requirements | D5: Data Integrations sources and targets | E5: Performance Test Plan | F5: Training Exercises | G5: Client led quarter end close | Donyati Support
B6: Workshops to review and finalize RTM | C6: Table Read of Design Document | D6: Calculations / Rules | F6: Frequently Asked Questions (FAQ)
A7: 2. Governance & Team Structure | D7: Workflows | E7: 2. System Integration Testing (SIT) | F7: Deliver Instructor Led (ILT) | G7: 2. Deliverables
A8: Establish Steering Committee | B8: 2. Deliverables | C8: 2. Deliverables | D8: Reports | E8: SIT Test Plan | G8: none
A9: Establish Core Team | B9: Schedule Requirements Workshops | C9: Design Workshops | D9: Data Conversion & Mapping | E9: SIT Tracking tool (Jira, DevOps, Excel)
A10: Establish SMEs for functional processes and IT | B10: Requirements Traceablity Matrix (RTM) | C10: Detailed Design Document | D10: Deployment and Cut-over Plan | F10: 2. Deliverables | G10: TOLL GATE - Go Live approval
A11: Establish Governance Board | B11: Sign off on RTM | C11: Updated timeline incorporating design requirments | E11: 2. User Acceptace Testing (UAT) | F11: Training Materials
A12: Establish Project Management structure and RACI | C12: Sign-off on Design Document | D12: 2. Security | E12: Client approved UAT Scripts | F12: Training Delivery
B13: TOLL GATE - approval of Requirements Traceability Matrix (RTM) | C13: Updated budget and staffing model based on Design | D13: User security & groups | E13: UAT tracking tool (Jira, DevOps, Excel) | F13: FAQ Sheets
A14: 3. Project Planning & Budgeting | C14: Change Order for scope change from initial SOW | E14: UAT Tester training
A15: Draft High Level implementation timeline (weeks / task) | C15: Roadmap - Phased Implementation plan | D15: 3. Deliverables | E15: Security set up
A16: Develop budget vs. actual tracking template for financial transparency | D16: Instance Strategy | E16: SmartView client install
A17: Risk, Action, Issue, Decision (RAID) Logs | C17: TOLL GATE - approval of design document, timeline and budget | D17: Architecture Diagram
D18: Data Conversion & Validation Strategy | E18: 3. Deliverables
A19: 4. Communications | D19: Testing Strategy | E19: Approved Performance
A20: Establish Status Meeting cadence | D20: Training Strategy | E20: SIT Exit Criteria sign off
A21: Establish Steering Committee cadence | D21: Change Management Strategy | E21: UAT Exit Criteria sign off
A22: Schedule Requirements Sessions | D22: Performance Testing Plan
D23: System Integration Test (SIT) Plan | E23: TOLL GATE - Training Entrance Criteria sign off
A24: 5. Deliverables | D24: User Acceptance Test (UAT) Plan
